<?xml version="1.0" encoding="UTF-8"?>
<!-- Generated by org.testng.reporters.JUnitReportReporter -->
<testsuite skipped="0" hostname="WTC-5159473-l2" name="WDPA_Application.WDPA_SmokeTest" tests="1" failures="1" timestamp="14 Dec 2018 22:14:56 GMT" time="57.054" errors="0">
  <testcase name="Pickup_Ground" time="57.054" classname="WDPA_Application.WDPA_SmokeTest">
    <failure type="java.lang.AssertionError" message="The system has experienced an unexpected problem and is unable to complete your request. Please contact FedEx Customer Service to schedule your pickup.">
      <![CDATA[java.lang.AssertionError: The system has experienced an unexpected problem and is unable to complete your request. Please contact FedEx Customer Service to schedule your pickup.
at org.testng.Assert.fail(Assert.java:96)
at WDPA_Application.WDPA_SmokeTest.Pickup_Ground(WDPA_SmokeTest.java:84)
at sun.reflect.NativeMethodAccessorImpl.invoke0(Native Method)
at sun.reflect.NativeMethodAccessorImpl.invoke(Unknown Source)
at sun.reflect.DelegatingMethodAccessorImpl.invoke(Unknown Source)
at java.lang.reflect.Method.invoke(Unknown Source)
at org.testng.internal.MethodInvocationHelper.invokeMethod(MethodInvocationHelper.java:124)
at org.testng.internal.Invoker.invokeMethod(Invoker.java:580)
at org.testng.internal.Invoker.invokeTestMethod(Invoker.java:716)
at org.testng.internal.TestMethodWithDataProviderMethodWorker.call(TestMethodWithDataProviderMethodWorker.java:71)
at org.testng.internal.TestMethodWithDataProviderMethodWorker.call(TestMethodWithDataProviderMethodWorker.java:14)
at java.util.concurrent.FutureTask.run(Unknown Source)
at java.util.concurrent.Executors$RunnableAdapter.call(Unknown Source)
at java.util.concurrent.FutureTask.run(Unknown Source)
at java.util.concurrent.ThreadPoolExecutor.runWorker(Unknown Source)
at java.util.concurrent.ThreadPoolExecutor$Worker.run(Unknown Source)
at java.lang.Thread.run(Unknown Source)
]]>
    </failure>
  </testcase> <!-- Pickup_Ground -->
</testsuite> <!-- WDPA_Application.WDPA_SmokeTest -->
